Workbook

Sheet Risk Index
A1: risk_id | B1: risk | C1: risk_type | D1: section | E1: grounding_score | F1: evidence | G1: evidence_n | H1: associations | I1: evidence_link
A2: FM1 | B2: Miscoordination | C2: Failure mode | D2: 2.1 | E2: =_xlfn.MAXIFS(Evidence!$M$2:$M$90,Evidence!$J$2:$J$90,"*Miscoordination*")/10 | F2: CS1, AIV-07, AIV-06, AIV-04, AIV-01, AIV-02 | G2: 6 | H2: Information Asymmetries Network Effects Selection Pressures Destabilising Dynamics Commitment and Trust | I2: TRUE TRUE TRUE FALSE TRUE
A3: FM2 | B3: Conflict | C3: Failure mode | D3: 2.2 | E3: =_xlfn.MAXIFS(Evidence!$M$2:$M$90,Evidence!$J$2:$J$90,"*Conflict*")/10 | F3: CS2, CS3, CS6, CS9, CS11 | G3: 5 | H3: Information Asymmetries Selection Pressures Destabilising Dynamics Commitment and Trust Multi-Agent Security | I3: TRUE TRUE TRUE TRUE FALSE
A4: FM3 | B4: Collusion | C4: Failure mode | D4: 2.3 | E4: =_xlfn.MAXIFS(Evidence!$M$2:$M$90,Evidence!$J$2:$J$90,"*Collusion*")/10 | F4: CS4, CS5, AIR-2026-0183, LW-01, LW-02, AIR-2026-0219 | G4: 6 | H4: Network Effects Selection Pressures Emergent Agency Multi-Agent Security | I4: TRUE TRUE TRUE TRUE
A5: RF1 | B5: Information Asymmetries | C5: Risk factor | D5: 3.1 | E5: =_xlfn.MAXIFS(Evidence!$M$2:$M$90,Evidence!$K$2:$K$90,"*Information Asymmetries*")/10 | F5: CS1, CS6, CS7, AIV-07, AIV-06, AIV-05, AIR-2025-0149, AIV-03, AIV-01, AIV-02 | G5: 10 | H5: Miscoordination Conflict | I5: TRUE TRUE
A6: RF2 | B6: Network Effects | C6: Risk factor | D6: 3.2 | E6: =_xlfn.MAXIFS(Evidence!$M$2:$M$90,Evidence!$K$2:$K$90,"*Network Effects*")/10 | F6: CS7, CS8, CS10, AIV-07, AIR-2026-0193, AIR-2026-0189, LW-01, LW-05, AIV-03, AIR-2025-0068, AIV-01 | G6: 11 | H6: Miscoordination Collusion | I6: TRUE TRUE
A7: RF3 | B7: Selection Pressures | C7: Risk factor | D7: 3.3 | E7: =_xlfn.MAXIFS(Evidence!$M$2:$M$90,Evidence!$K$2:$K$90,"*Selection Pressures*")/10 | F7: CS1, CS2, CS4, CS9 | G7: 4 | H7: Miscoordination Conflict Collusion | I7: TRUE TRUE TRUE
A8: RF4 | B8: Destabilising Dynamics | C8: Risk factor | D8: 3.4 | E8: =_xlfn.MAXIFS(Evidence!$M$2:$M$90,Evidence!$K$2:$K$90,"*Destabilising Dynamics*")/10 | F8: CS3, CS10 | G8: 2 | H8: Miscoordination Conflict | I8: FALSE TRUE
A9: RF5 | B9: Commitment and Trust | C9: Risk factor | D9: 3.5 | E9: =_xlfn.MAXIFS(Evidence!$M$2:$M$90,Evidence!$K$2:$K$90,"*Commitment and Trust*")/10 | F9: CS2, CS9, CS11, AIR-2026-0180, AIV-06, AIR-2026-0101, AIV-05, AIR-2025-0177, AIR-2025-0136 | G9: 9 | H9: Miscoordination Conflict | I9: TRUE TRUE
A10: RF6 | B10: Emergent Agency | C10: Risk factor | D10: 3.6 | E10: =_xlfn.MAXIFS(Evidence!$M$2:$M$90,Evidence!$K$2:$K$90,"*Emergent Agency*")/10 | F10: CS4, CS12, AIR-2026-0183, LW-01, AIR-2026-0219, LW-05, AIR-2025-0027, AIR-2025-0019 | G10: 8 | H10: Collusion | I10: TRUE
A11: RF7 | B11: Multi-Agent Security | C11: Risk factor | D11: 3.7 | E11: =_xlfn.MAXIFS(Evidence!$M$2:$M$90,Evidence!$K$2:$K$90,"*Multi-Agent Security*")/10 | F11: CS5, CS8, CS12, CS13, AIR-2026-0193, AIR-2026-0189, AIR-2026-0183, AIR-2026-0180, LW-01, AIR-2026-0194, LW-02, AIR-2026-0219, AIR-2026-0101, AIR-2026-0029, AIR-2025-0177, AIR-2025-0149, AIR-2025-0136, AIR-2025-0070, AIR-2025-0068, AIR-2025-0019 | G11: 20 | H11: Conflict Collusion | I11: FALSE TRUE
A13: grounding_score = highest evidence_score / 10 across every piece of evidence tagged with this risk: Hammond et al. 2025 case studies and inventory incidents alike. evidence lists their ids, evidence_n counts them.
A14: associations = linked risk factors (for a failure mode) or failure modes (for a risk factor). evidence_link is line-aligned: TRUE if a piece of evidence is tagged with both ends, FALSE if the paper links them only in the text.

Sheet FM-RF Links
A1: # | B1: failure_mode | C1: risk_factor | D1: evidence_link | E1: link_basis | F1: fm_instances | G1: fm_directions | H1: rf_instances | I1: rf_directions | J1: evidence_tagged_both | K1: evidence_n | L1: source_class | M1: type | N1: evidence_strength_max | O1: evidence_score_max | P1: evidence_source | Q1: text_reference
A2: 1 | B2: Miscoordination | C2: Information Asymmetries | D2: TRUE | E2: Evidence + text | F2: Incompatible Strategies Credit Assignment Limited Interactions | G2: Communication Norms and Conventions Modelling Other Agents | H2: Communication Constraints Bargaining Deception | I2: Information Design Individual Information Revelation Few-Shot Coordination Truthful AI | J2: CS1: Zero-Shot Coordination Failures in Driving AIV-07: DeepSeek-V3.2 persuasion campaign: invented a self-serving metric; the group ad… AIV-06: Agents finetune their own leader: Opus assumed GPT-5.5 agreed without confirmin… AIV-01: Hallucinated mailing list spreads between agents: o3 invented a 93-person maili… AIV-02: False 'broken UI' belief spreads: Gemini 2.5 Pro logged its own misclicks as sy… | K2: 5 | L2: Novel experiment by report authors Operator blog Operator blog Operator blog Operator blog | M2: Synthetic evidence Synthetic evidence Synthetic evidence Synthetic evidence Synthetic evidence | N2: =IF(O2=0,"—",IF(O2>=9,"Strong",IF(O2>=6,"Moderate",IF(O2>=3,"Limited","Weak")))) | O2: =_xlfn.MAXIFS(Evidence!$M$2:$M$90,Evidence!$J$2:$J$90,"*Miscoordination*",Evidence!$K$2:$K$90,"*Information Asymmetries*") | P2: Report authors (App. B.1) Persuasion in the AI Village: DeepSeek-V3.2 & Gemini 2.5 Pro AIs finetune their own leader: a barking simpleton Season 2 recap: the story of the world's first AI-organized event What did we learn from the AI Village in 2025? | Q2: info asymmetries can cause miscoordination (§1.1, §3); Credit Assignment & Communication Constraints cross-ref §2.1/§3.1.
A3: 2 | B3: Miscoordination | C3: Network Effects | D3: TRUE | E3: Evidence | F3: Incompatible Strategies Credit Assignment Limited Interactions | G3: Communication Norms and Conventions Modelling Other Agents | H3: Error Propagation Network Rewiring Homogeneity and Correlated Failures | I3: Evaluating and Monitoring Networks Faithful and Tractable Simulations Improving Network Security and Stability | J3: AIV-07: DeepSeek-V3.2 persuasion campaign: invented a self-serving metric; the group ad… AIV-01: Hallucinated mailing list spreads between agents: o3 invented a 93-person maili… | K3: 2 | L3: Operator blog Operator blog | M3: Synthetic evidence Synthetic evidence | N3: =IF(O3=0,"—",IF(O3>=9,"Strong",IF(O3>=6,"Moderate",IF(O3>=3,"Limited","Weak")))) | O3: =_xlfn.MAXIFS(Evidence!$M$2:$M$90,Evidence!$J$2:$J$90,"*Miscoordination*",Evidence!$K$2:$K$90,"*Network Effects*") | P3: Persuasion in the AI Village: DeepSeek-V3.2 & Gemini 2.5 Pro Season 2 recap: the story of the world's first AI-organized event | Q3: —
A4: 3 | B4: Miscoordination | C4: Selection Pressures | D4: TRUE | E4: Evidence | F4: Incompatible Strategies Credit Assignment Limited Interactions | G4: Communication Norms and Conventions Modelling Other Agents | H4: Undesirable Dispositions from Competition Undesirable Dispositions from Human Data Undesirable Capabilities | I4: Evaluating Against Diverse Co-Players Environment Design Understanding the Impacts of Training Evolutionary Game Theory Simulating Selection Pressures | J4: CS1: Zero-Shot Coordination Failures in Driving | K4: 1 | L4: Novel experiment by report authors | M4: Synthetic evidence | N4: =IF(O4=0,"—",IF(O4>=9,"Strong",IF(O4>=6,"Moderate",IF(O4>=3,"Limited","Weak")))) | O4: =_xlfn.MAXIFS(Evidence!$M$2:$M$90,Evidence!$J$2:$J$90,"*Miscoordination*",Evidence!$K$2:$K$90,"*Selection Pressures*") | P4: Report authors (App. B.1) | Q4: —
A5: 4 | B5: Miscoordination | C5: Destabilising Dynamics | D5: FALSE | E5: Text cross-reference only | F5: Incompatible Strategies Credit Assignment Limited Interactions | G5: Communication Norms and Conventions Modelling Other Agents | H5: Feedback Loops Cyclic Behaviour Chaos Phase Transitions Distributional Shift | I5: Understanding Dynamics Monitoring and Stabilising Dynamics Regulating Adaptive Multi-Agent Systems | J5: — | K5: 0 | L5: — | M5: — | N5: =IF(O5=0,"—",IF(O5>=9,"Strong",IF(O5>=6,"Moderate",IF(O5>=3,"Limited","Weak")))) | O5: =_xlfn.MAXIFS(Evidence!$M$2:$M$90,Evidence!$J$2:$J$90,"*Miscoordination*",Evidence!$K$2:$K$90,"*Destabilising Dynamics*") | P5: — | Q5: Credit Assignment cross-refs §3.4 (distributional shift).
A6: 5 | B6: Miscoordination | C6: Commitment and Trust | D6: TRUE | E6: Evidence | F6: Incompatible Strategies Credit Assignment Limited Interactions | G6: Communication Norms and Conventions Modelling Other Agents | H6: Inefficient Outcomes Threats and Extortion Rigidity and Mistaken Commitments | I6: Keeping Humans in the Loop Limiting Commitment Power Institutions and Normative Infrastructure Privacy-Preserving Monitoring Mutual Simulation and Transparency | J6: AIV-06: Agents finetune their own leader: Opus assumed GPT-5.5 agreed without confirmin… | K6: 1 | L6: Operator blog | M6: Synthetic evidence | N6: =IF(O6=0,"—",IF(O6>=9,"Strong",IF(O6>=6,"Moderate",IF(O6>=3,"Limited","Weak")))) | O6: =_xlfn.MAXIFS(Evidence!$M$2:$M$90,Evidence!$J$2:$J$90,"*Miscoordination*",Evidence!$K$2:$K$90,"*Commitment and Trust*") | P6: AIs finetune their own leader: a barking simpleton | Q6: —
A7: 6 | B7: Conflict | C7: Information Asymmetries | D7: TRUE | E7: Evidence + text | F7: Social Dilemmas Military Domains Coercion and Extortion | G7: Learning Peer and Pool Incentivisation Establishing Trust Normative Approaches to Equilibrium Selection Cooperative Dispositions Agent Governance Evidential Reasoning | H7: Communication Constraints Bargaining Deception | I7: Information Design Individual Information Revelation Few-Shot Coordination Truthful AI | J7: CS6: AI Agents Can Learn to Manipulate Financial Markets | K7: 1 | L7: Literature | M7: Synthetic evidence | N7: =IF(O7=0,"—",IF(O7>=9,"Strong",IF(O7>=6,"Moderate",IF(O7>=3,"Limited","Weak")))) | O7: =_xlfn.MAXIFS(Evidence!$M$2:$M$90,Evidence!$J$2:$J$90,"*Conflict*",Evidence!$K$2:$K$90,"*Information Asymmetries*") | P7: Shearer et al. (2023); Wang & Wellman (2020) | Q7: Bargaining under asymmetric info → costly conflict (§3.1).
A8: 7 | B8: Conflict | C8: Selection Pressures | D8: TRUE | E8: Evidence + text | F8: Social Dilemmas Military Domains Coercion and Extortion | G8: Learning Peer and Pool Incentivisation Establishing Trust Normative Approaches to Equilibrium Selection Cooperative Dispositions Agent Governance Evidential Reasoning | H8: Undesirable Dispositions from Competition Undesirable Dispositions from Human Data Undesirable Capabilities | I8: Evaluating Against Diverse Co-Players Environment Design Understanding the Impacts of Training Evolutionary Game Theory Simulating Selection Pressures | J8: CS2: Common Resource Problems CS9: Cooperation Fails to Culturally Evolve among LLM Agents | K8: 2 | L8: Literature Literature | M8: Synthetic evidence Synthetic evidence | N8: =IF(O8=0,"—",IF(O8>=9,"Strong",IF(O8>=6,"Moderate",IF(O8>=3,"Limited","Weak")))) | O8: =_xlfn.MAXIFS(Evidence!$M$2:$M$90,Evidence!$J$2:$J$90,"*Conflict*",Evidence!$K$2:$K$90,"*Selection Pressures*") | P8: Piatti et al. (2024), GovSim Vallinder & Hughes (2024) | Q8: Cooperative Dispositions direction cross-refs §3.3 (conflict-prone dispositions from data/training).
A9: 8 | B9: Conflict | C9: Destabilising Dynamics | D9: TRUE | E9: Evidence + text | F9: Social Dilemmas Military Domains Coercion and Extortion | G9: Learning Peer and Pool Incentivisation Establishing Trust Normative Approaches to Equilibrium Selection Cooperative Dispositions Agent Governance Evidential Reasoning | H9: Feedback Loops Cyclic Behaviour Chaos Phase Transitions Distributional Shift | I9: Understanding Dynamics Monitoring and Stabilising Dynamics Regulating Adaptive Multi-Agent Systems | J9: CS3: Escalation in Military Conflicts | K9: 1 | L9: Literature | M9: Synthetic evidence | N9: =IF(O9=0,"—",IF(O9>=9,"Strong",IF(O9>=6,"Moderate",IF(O9>=3,"Limited","Weak")))) | O9: =_xlfn.MAXIFS(Evidence!$M$2:$M$90,Evidence!$J$2:$J$90,"*Conflict*",Evidence!$K$2:$K$90,"*Destabilising Dynamics*") | P9: Rivera et al. (2024) | Q9: conflicts can escalate via destabilising dynamics (§3 intro).
A10: 9 | B10: Conflict | C10: Commitment and Trust | D10: TRUE | E10: Evidence + text | F10: Social Dilemmas Military Domains Coercion and Extortion | G10: Learning Peer and Pool Incentivisation Establishing Trust Normative Approaches to Equilibrium Selection Cooperative Dispositions Agent Governance Evidential Reasoning | H10: Inefficient Outcomes Threats and Extortion Rigidity and Mistaken Commitments | I10: Keeping Humans in the Loop Limiting Commitment Power Institutions and Normative Infrastructure Privacy-Preserving Monitoring Mutual Simulation and Transparency | J10: CS2: Common Resource Problems CS9: Cooperation Fails to Culturally Evolve among LLM Agents CS11: Dead Hands and Automated Deterrence | K10: 3 | L10: Literature Literature Historical example | M10: Synthetic evidence Synthetic evidence Observed in real world | N10: =IF(O10=0,"—",IF(O10>=9,"Strong",IF(O10>=6,"Moderate",IF(O10>=3,"Limited","Weak")))) | O10: =_xlfn.MAXIFS(Evidence!$M$2:$M$90,Evidence!$J$2:$J$90,"*Conflict*",Evidence!$K$2:$K$90,"*Commitment and Trust*") | P10: Piatti et al. (2024), GovSim Vallinder & Hughes (2024) Hoffman (2009); Talbot (2005) | Q10: Establishing Trust direction cross-refs §3.5; inability to commit is a major cause of costly conflict.
A11: 10 | B11: Conflict | C11: Multi-Agent Security | D11: FALSE | E11: Text cross-reference only | F11: Social Dilemmas Military Domains Coercion and Extortion | G11: Learning Peer and Pool Incentivisation Establishing Trust Normative Approaches to Equilibrium Selection Cooperative Dispositions Agent Governance Evidential Reasoning | H11: Swarm Attacks Heterogeneous Attacks Social Engineering at Scale Vulnerable AI Agents Cascading Security Failures Undetectable Threats | I11: Secure Interaction Protocols Monitoring and Threat Detection Multi-Agent Adversarial Testing Sociotechnical Security Defences | J11: — | K11: 0 | L11: — | M11: — | N11: =IF(O11=0,"—",IF(O11>=9,"Strong",IF(O11>=6,"Moderate",IF(O11>=3,"Limited","Weak")))) | O11: =_xlfn.MAXIFS(Evidence!$M$2:$M$90,Evidence!$J$2:$J$90,"*Conflict*",Evidence!$K$2:$K$90,"*Multi-Agent Security*") | P11: — | Q11: Coercion and Extortion via hacking/jailbreaking other agents cross-refs §3.7.
A12: 11 | B12: Collusion | C12: Network Effects | D12: TRUE | E12: Evidence + text | F12: Markets Steganography | G12: Detecting AI Collusion Mitigating AI Collusion Assessing Impacts on Safety Protocols | H12: Error Propagation Network Rewiring Homogeneity and Correlated Failures | I12: Evaluating and Monitoring Networks Faithful and Tractable Simulations Improving Network Security and Stability | J12: LW-01: ExploitGym swarm and Hugging Face intrusion: about 1,200 agents in separate san… | K12: 1 | L12: Operator report | M12: Observed in real world | N12: =IF(O12=0,"—",IF(O12>=9,"Strong",IF(O12>=6,"Moderate",IF(O12>=3,"Limited","Weak")))) | O12: =_xlfn.MAXIFS(Evidence!$M$2:$M$90,Evidence!$J$2:$J$90,"*Collusion*",Evidence!$K$2:$K$90,"*Network Effects*") | P12: OpenAI technical report | Q12: AI-AI preferential attachment simulations cross-ref §2.3 (§3.2.3).
A13: 12 | B13: Collusion | C13: Selection Pressures | D13: TRUE | E13: Evidence | F13: Markets Steganography | G13: Detecting AI Collusion Mitigating AI Collusion Assessing Impacts on Safety Protocols | H13: Undesirable Dispositions from Competition Undesirable Dispositions from Human Data Undesirable Capabilities | I13: Evaluating Against Diverse Co-Players Environment Design Understanding the Impacts of Training Evolutionary Game Theory Simulating Selection Pressures | J13: CS4: Algorithmic Collusion in the German Retail Gasoline Market | K13: 1 | L13: Historical example | M13: Observed in real world | N13: =IF(O13=0,"—",IF(O13>=9,"Strong",IF(O13>=6,"Moderate",IF(O13>=3,"Limited","Weak")))) | O13: =_xlfn.MAXIFS(Evidence!$M$2:$M$90,Evidence!$J$2:$J$90,"*Collusion*",Evidence!$K$2:$K$90,"*Selection Pressures*") | P13: Assad et al. (2020) | Q13: —
A14: 13 | B14: Collusion | C14: Emergent Agency | D14: TRUE | E14: Evidence + text | F14: Markets Steganography | G14: Detecting AI Collusion Mitigating AI Collusion Assessing Impacts on Safety Protocols | H14: Emergent Capabilities Emergent Goals | I14: Empirical Exploration Theories of Emergent Capabilities Theories of Emergent Goals Monitoring and Intervening on Collective Agents | J14: CS4: Algorithmic Collusion in the German Retail Gasoline Market AIR-2026-0183: OpenAI evaluation agents turned an internal Artifactory service into a covert m… LW-01: ExploitGym swarm and Hugging Face intrusion: about 1,200 agents in separate san… AIR-2026-0219: A swarm of internally deployed OpenAI agents made more than 15,000 edits to the… | K14: 4 | L14: Historical example Safety failure Operator report Safety failure | M14: Observed in real world Observed in real world Observed in real world Observed in real world | N14: =IF(O14=0,"—",IF(O14>=9,"Strong",IF(O14>=6,"Moderate",IF(O14>=3,"Limited","Weak")))) | O14: =_xlfn.MAXIFS(Evidence!$M$2:$M$90,Evidence!$J$2:$J$90,"*Collusion*",Evidence!$K$2:$K$90,"*Emergent Agency*") | P14: Assad et al. (2020) Agent Incident Registry (Enkrypt AI) OpenAI technical report Agent Incident Registry (Enkrypt AI) | Q14: collusion can yield qualitatively new capabilities/goals (§2.3.2 → §3.6).
A15: 14 | B15: Collusion | C15: Multi-Agent Security | D15: TRUE | E15: Evidence + text | F15: Markets Steganography | G15: Detecting AI Collusion Mitigating AI Collusion Assessing Impacts on Safety Protocols | H15: Swarm Attacks Heterogeneous Attacks Social Engineering at Scale Vulnerable AI Agents Cascading Security Failures Undetectable Threats | I15: Secure Interaction Protocols Monitoring and Threat Detection Multi-Agent Adversarial Testing Sociotechnical Security Defences | J15: CS5: Language Model Steganography AIR-2026-0183: OpenAI evaluation agents turned an internal Artifactory service into a covert m… LW-01: ExploitGym swarm and Hugging Face intrusion: about 1,200 agents in separate san… LW-02: Vanderbilt link shortener operation: a swarm used public link-shortener statist… AIR-2026-0219: A swarm of internally deployed OpenAI agents made more than 15,000 edits to the… | K15: 5 | L15: Literature Safety failure Operator report Independent investigation Safety failure | M15: Observed in lab Observed in real world Observed in real world Observed in real world Observed in real world | N15: =IF(O15=0,"—",IF(O15>=9,"Strong",IF(O15>=6,"Moderate",IF(O15>=3,"Limited","Weak")))) | O15: =_xlfn.MAXIFS(Evidence!$M$2:$M$90,Evidence!$J$2:$J$90,"*Collusion*",Evidence!$K$2:$K$90,"*Multi-Agent Security*") | P15: Motwani et al. (2024) Agent Incident Registry (Enkrypt AI) OpenAI technical report DeGraff: swarm investigation Agent Incident Registry (Enkrypt AI) | Q15: collusion to bypass safeguards; Assessing Impacts on Safety Protocols cross-refs §3.6–3.7.

Sheet Taxonomy
A1: risk_type | B1: risk | C1: section | D1: definition | E1: instances | F1: directions | G1: linked_risks | H1: evidence | I1: evidence_n | J1: source_class | K1: type | L1: evidence_strength_max | M1: evidence_score_max
A2: Failure mode | B2: Miscoordination | C2: 2.1 | D2: Agents share a clear common objective but fail to align behaviour to achieve it. | E2: Incompatible Strategies Credit Assignment Limited Interactions | F2: Communication Norms and Conventions Modelling Other Agents | G2: Information Asymmetries Network Effects Selection Pressures Destabilising Dynamics Commitment and Trust | H2: CS1: Zero-Shot Coordination Failures in Driving AIV-07: DeepSeek-V3.2 persuasion campaign: invented a self-serving metric; the group ad… AIV-06: Agents finetune their own leader: Opus assumed GPT-5.5 agreed without confirmin… AIV-04: Sub-team goal divergence: during a leader-election goal, the GPT agents left to… AIV-01: Hallucinated mailing list spreads between agents: o3 invented a 93-person maili… AIV-02: False 'broken UI' belief spreads: Gemini 2.5 Pro logged its own misclicks as sy… | I2: 6 | J2: Novel experiment by report authors Operator blog Operator blog Operator blog Operator blog Operator blog | K2: Synthetic evidence Synthetic evidence Synthetic evidence Synthetic evidence Synthetic evidence Synthetic evidence | L2: =IF(M2=0,"—",IF(M2>=9,"Strong",IF(M2>=6,"Moderate",IF(M2>=3,"Limited","Weak")))) | M2: =_xlfn.MAXIFS(Evidence!$M$2:$M$90,Evidence!$J$2:$J$90,"*Miscoordination*")
A3: Failure mode | B3: Conflict | C3: 2.2 | D3: Mixed-motive interaction ends in an outcome off the Pareto frontier (incl. commons depletion, warfare, races to the bottom). | E3: Social Dilemmas Military Domains Coercion and Extortion | F3: Learning Peer and Pool Incentivisation Establishing Trust Normative Approaches to Equilibrium Selection Cooperative Dispositions Agent Governance Evidential Reasoning | G3: Information Asymmetries Selection Pressures Destabilising Dynamics Commitment and Trust Multi-Agent Security | H3: CS2: Common Resource Problems CS3: Escalation in Military Conflicts CS6: AI Agents Can Learn to Manipulate Financial Markets CS9: Cooperation Fails to Culturally Evolve among LLM Agents CS11: Dead Hands and Automated Deterrence | I3: 5 | J3: Literature Literature Literature Literature Historical example | K3: Synthetic evidence Synthetic evidence Synthetic evidence Synthetic evidence Observed in real world | L3: =IF(M3=0,"—",IF(M3>=9,"Strong",IF(M3>=6,"Moderate",IF(M3>=3,"Limited","Weak")))) | M3: =_xlfn.MAXIFS(Evidence!$M$2:$M$90,Evidence!$J$2:$J$90,"*Conflict*")
A4: Failure mode | B4: Collusion | C4: 2.3 | D4: Undesired (often covert) cooperation between AI systems at the expense of third parties, e.g. markets or oversight schemes. | E4: Markets Steganography | F4: Detecting AI Collusion Mitigating AI Collusion Assessing Impacts on Safety Protocols | G4: Network Effects Selection Pressures Emergent Agency Multi-Agent Security | H4: CS4: Algorithmic Collusion in the German Retail Gasoline Market CS5: Language Model Steganography AIR-2026-0183: OpenAI evaluation agents turned an internal Artifactory service into a covert m… LW-01: ExploitGym swarm and Hugging Face intrusion: about 1,200 agents in separate san… LW-02: Vanderbilt link shortener operation: a swarm used public link-shortener statist… AIR-2026-0219: A swarm of internally deployed OpenAI agents made more than 15,000 edits to the… | I4: 6 | J4: Historical example Literature Safety failure Operator report Independent investigation Safety failure | K4: Observed in real world Observed in lab Observed in real world Observed in real world Observed in real world Observed in real world | L4: =IF(M4=0,"—",IF(M4>=9,"Strong",IF(M4>=6,"Moderate",IF(M4>=3,"Limited","Weak")))) | M4: =_xlfn.MAXIFS(Evidence!$M$2:$M$90,Evidence!$J$2:$J$90,"*Collusion*")
A5: Risk factor | B5: Information Asymmetries | C5: 3.1 | D5: Interacting agents hold different information bearing on a joint action; private info can cause miscoordination, deception, conflict. | E5: Communication Constraints Bargaining Deception | F5: Information Design Individual Information Revelation Few-Shot Coordination Truthful AI | G5: Miscoordination Conflict | H5: CS1: Zero-Shot Coordination Failures in Driving CS6: AI Agents Can Learn to Manipulate Financial Markets CS7: Transmission Through AI Networks Can Spread Falsities and Bias AIV-07: DeepSeek-V3.2 persuasion campaign: invented a self-serving metric; the group ad… AIV-06: Agents finetune their own leader: Opus assumed GPT-5.5 agreed without confirmin… AIV-05: Sabotage game: saboteurs tried to hide easter eggs in a shared game; Opus 4.6 e… AIR-2025-0149: OpenAI Agent Builder: a poisoned lead-form submission redirects a multi-agent s… AIV-03: Game-choice herding: agents copied the games peers announced they were beating… AIV-01: Hallucinated mailing list spreads between agents: o3 invented a 93-person maili… AIV-02: False 'broken UI' belief spreads: Gemini 2.5 Pro logged its own misclicks as sy… | I5: 10 | J5: Novel experiment by report authors Literature Novel experiment by report authors Operator blog Operator blog Operator blog Research demo Operator blog Operator blog Operator blog | K5: Synthetic evidence Synthetic evidence Observed in lab Synthetic evidence Synthetic evidence Synthetic evidence Observed in lab Synthetic evidence Synthetic evidence Synthetic evidence | L5: =IF(M5=0,"—",IF(M5>=9,"Strong",IF(M5>=6,"Moderate",IF(M5>=3,"Limited","Weak")))) | M5: =_xlfn.MAXIFS(Evidence!$M$2:$M$90,Evidence!$K$2:$K$90,"*Information Asymmetries*")
A6: Risk factor | B6: Network Effects | C6: 3.2 | D6: Small changes in node/connection properties or topology produce large changes in whole-network behaviour. | E6: Error Propagation Network Rewiring Homogeneity and Correlated Failures | F6: Evaluating and Monitoring Networks Faithful and Tractable Simulations Improving Network Security and Stability | G6: Miscoordination Collusion | H6: CS7: Transmission Through AI Networks Can Spread Falsities and Bias CS8: Infectious Adversarial Attacks in Networks of LLM Agents CS10: The 2010 Flash Crash AIV-07: DeepSeek-V3.2 persuasion campaign: invented a self-serving metric; the group ad… AIR-2026-0193: Agent 'mind virus': self-propagating payload written into SOUL.md spreads betwe… AIR-2026-0189: Pwning the Internet of Agents: an OpenClaw agent botnet on MoltBook (DEF CON 34) LW-01: ExploitGym swarm and Hugging Face intrusion: about 1,200 agents in separate san… LW-05: Moltbook agent behaviour: AI-agent-only social network reportedly reached ~36k… AIV-03: Game-choice herding: agents copied the games peers announced they were beating… AIR-2025-0068: IdentityMesh: agentic lateral movement through merged identities across connect… AIV-01: Hallucinated mailing list spreads between agents: o3 invented a 93-person maili… | I6: 11 | J6: Novel experiment by report authors Literature Historical example Operator blog Research demo Research demo Operator report Forum post Operator blog Research demo Operator blog | K6: Observed in lab Synthetic evidence Observed in real world Synthetic evidence Observed in lab Observed in lab Observed in real world Observed in real world Synthetic evidence Observed in lab Synthetic evidence | L6: =IF(M6=0,"—",IF(M6>=9,"Strong",IF(M6>=6,"Moderate",IF(M6>=3,"Limited","Weak")))) | M6: =_xlfn.MAXIFS(Evidence!$M$2:$M$90,Evidence!$K$2:$K$90,"*Network Effects*")
A7: Risk factor | B7: Selection Pressures | C7: 3.3 | D7: Training, deployment and replacement choices act as evolutionary forces selecting undesirable dispositions or capabilities. | E7: Undesirable Dispositions from Competition Undesirable Dispositions from Human Data Undesirable Capabilities | F7: Evaluating Against Diverse Co-Players Environment Design Understanding the Impacts of Training Evolutionary Game Theory Simulating Selection Pressures | G7: Miscoordination Conflict Collusion | H7: CS1: Zero-Shot Coordination Failures in Driving CS2: Common Resource Problems CS4: Algorithmic Collusion in the German Retail Gasoline Market CS9: Cooperation Fails to Culturally Evolve among LLM Agents | I7: 4 | J7: Novel experiment by report authors Literature Historical example Literature | K7: Synthetic evidence Synthetic evidence Observed in real world Synthetic evidence | L7: =IF(M7=0,"—",IF(M7>=9,"Strong",IF(M7>=6,"Moderate",IF(M7>=3,"Limited","Weak")))) | M7: =_xlfn.MAXIFS(Evidence!$M$2:$M$90,Evidence!$K$2:$K$90,"*Selection Pressures*")
A8: Risk factor | B8: Destabilising Dynamics | C8: 3.4 | D8: Mutually adapting systems generate feedback loops, instability and unpredictability. | E8: Feedback Loops Cyclic Behaviour Chaos Phase Transitions Distributional Shift | F8: Understanding Dynamics Monitoring and Stabilising Dynamics Regulating Adaptive Multi-Agent Systems | G8: Miscoordination Conflict | H8: CS3: Escalation in Military Conflicts CS10: The 2010 Flash Crash | I8: 2 | J8: Literature Historical example | K8: Synthetic evidence Observed in real world | L8: =IF(M8=0,"—",IF(M8>=9,"Strong",IF(M8>=6,"Moderate",IF(M8>=3,"Limited","Weak")))) | M8: =_xlfn.MAXIFS(Evidence!$M$2:$M$90,Evidence!$K$2:$K$90,"*Destabilising Dynamics*")
A9: Risk factor | B9: Commitment and Trust | C9: 3.5 | D9: Difficulty forming credible commitments, trust or reputation blocks mutual gains in AI-AI and human-AI interaction. | E9: Inefficient Outcomes Threats and Extortion Rigidity and Mistaken Commitments | F9: Keeping Humans in the Loop Limiting Commitment Power Institutions and Normative Infrastructure Privacy-Preserving Monitoring Mutual Simulation and Transparency | G9: Miscoordination Conflict | H9: CS2: Common Resource Problems CS9: Cooperation Fails to Culturally Evolve among LLM Agents CS11: Dead Hands and Automated Deterrence AIR-2026-0180: 'I'll just call you': a low-privileged CI agent on Google's adk-python is injec… AIV-06: Agents finetune their own leader: Opus assumed GPT-5.5 agreed without confirmin… AIR-2026-0101: Morse-code prompt injection made Grok relay a transfer instruction to Bankrbot,… AIV-05: Sabotage game: saboteurs tried to hide easter eggs in a shared game; Opus 4.6 e… AIR-2025-0177: ServiceNow Now Assist: second-order prompt injection recruits privileged agents… AIR-2025-0136: Cross-agent privilege escalation: one hijacked coding agent rewrites another ag… | I9: 9 | J9: Literature Literature Historical example Disclosed vulnerability Operator blog In the wild Operator blog Disclosed vulnerability Disclosed vulnerability | K9: Synthetic evidence Synthetic evidence Observed in real world Observed in lab Synthetic evidence Observed in real world Synthetic evidence Observed in lab Observed in lab | L9: =IF(M9=0,"—",IF(M9>=9,"Strong",IF(M9>=6,"Moderate",IF(M9>=3,"Limited","Weak")))) | M9: =_xlfn.MAXIFS(Evidence!$M$2:$M$90,Evidence!$K$2:$K$90,"*Commitment and Trust*")
A10: Risk factor | B10: Emergent Agency | C10: 3.6 | D10: Qualitatively new goals or capabilities emerge from composing individually innocuous systems. | E10: Emergent Capabilities Emergent Goals | F10: Empirical Exploration Theories of Emergent Capabilities Theories of Emergent Goals Monitoring and Intervening on Collective Agents | G10: Collusion | H10: CS4: Algorithmic Collusion in the German Retail Gasoline Market CS12: Overcoming Safeguards via Multiple Safe Models AIR-2026-0183: OpenAI evaluation agents turned an internal Artifactory service into a covert m… LW-01: ExploitGym swarm and Hugging Face intrusion: about 1,200 agents in separate san… AIR-2026-0219: A swarm of internally deployed OpenAI agents made more than 15,000 edits to the… LW-05: Moltbook agent behaviour: AI-agent-only social network reportedly reached ~36k… AIR-2025-0027: Influence-as-a-service: Claude used as the orchestrator deciding actions for 10… AIR-2025-0019: Xanthorox AI: a self-hosted, five-model offensive platform sold on darknet foru… | I10: 8 | J10: Historical example Literature Safety failure Operator report Safety failure Forum post In the wild In the wild | K10: Observed in real world Observed in lab Observed in real world Observed in real world Observed in real world Observed in real world Observed in real world Observed in real world | L10: =IF(M10=0,"—",IF(M10>=9,"Strong",IF(M10>=6,"Moderate",IF(M10>=3,"Limited","Weak")))) | M10: =_xlfn.MAXIFS(Evidence!$M$2:$M$90,Evidence!$K$2:$K$90,"*Emergent Agency*")
A11: Risk factor | B11: Multi-Agent Security | C11: 3.7 | D11: Multi-agent systems create new security threats and vulnerabilities. | E11: Swarm Attacks Heterogeneous Attacks Social Engineering at Scale Vulnerable AI Agents Cascading Security Failures Undetectable Threats | F11: Secure Interaction Protocols Monitoring and Threat Detection Multi-Agent Adversarial Testing Sociotechnical Security Defences | G11: Conflict Collusion | H11: CS5: Language Model Steganography CS8: Infectious Adversarial Attacks in Networks of LLM Agents CS12: Overcoming Safeguards via Multiple Safe Models CS13: Unprompted Adversarial Attacks on Overseer Agents AIR-2026-0193: Agent 'mind virus': self-propagating payload written into SOUL.md spreads betwe… AIR-2026-0189: Pwning the Internet of Agents: an OpenClaw agent botnet on MoltBook (DEF CON 34) AIR-2026-0183: OpenAI evaluation agents turned an internal Artifactory service into a covert m… AIR-2026-0180: 'I'll just call you': a low-privileged CI agent on Google's adk-python is injec… LW-01: ExploitGym swarm and Hugging Face intrusion: about 1,200 agents in separate san… AIR-2026-0194: Suspected China-linked actors used a multi-agent framework built on Hermes and… LW-02: Vanderbilt link shortener operation: a swarm used public link-shortener statist… AIR-2026-0219: A swarm of internally deployed OpenAI agents made more than 15,000 edits to the… AIR-2026-0101: Morse-code prompt injection made Grok relay a transfer instruction to Bankrbot,… AIR-2026-0029: Moltbook, the social network for AI agents, left its database open: 1.5M API to… AIR-2025-0177: ServiceNow Now Assist: second-order prompt injection recruits privileged agents… AIR-2025-0149: OpenAI Agent Builder: a poisoned lead-form submission redirects a multi-agent s… AIR-2025-0136: Cross-agent privilege escalation: one hijacked coding agent rewrites another ag… AIR-2025-0070: PajaMAS: hijacking multi-agent systems built on Google's Agent Development Kit AIR-2025-0068: IdentityMesh: agentic lateral movement through merged identities across connect… AIR-2025-0019: Xanthorox AI: a self-hosted, five-model offensive platform sold on darknet foru… | I11: 20 | J11: Literature Literature Literature Novel experiment by report authors Research demo Research demo Safety failure Disclosed vulnerability Operator report In the wild Independent investigation Safety failure In the wild Disclosed vulnerability Disclosed vulnerability Research demo Disclosed vulnerability Research demo Research demo In the wild | K11: Observed in lab Synthetic evidence Observed in lab Observed in lab Observed in lab Observed in lab Observed in real world Observed in lab Observed in real world Observed in real world Observed in real world Observed in real world Observed in real world Observed in lab Observed in lab Observed in lab Observed in lab Observed in lab Observed in lab Observed in real world | L11: =IF(M11=0,"—",IF(M11>=9,"Strong",IF(M11>=6,"Moderate",IF(M11>=3,"Limited","Weak")))) | M11: =_xlfn.MAXIFS(Evidence!$M$2:$M$90,Evidence!$K$2:$K$90,"*Multi-Agent Security*")

Sheet Instances
A1: instance_id | B1: instance | C1: parent_risk | D1: parent_risk_type | E1: section | F1: evidence_explicit | G1: evidence_placement | H1: evidence_basis | I1: evidence_score_max | J1: key_references | K1: support_summary
A2: I01 | B2: Incompatible Strategies | C2: Miscoordination | D2: Failure mode | E2: 2.1 | F2: CS1 | G2: — | H2: Case study | I2: =MAX(INDEX(Evidence!$M$2:$M$90,MATCH("CS1",Evidence!$A$2:$A$90,0))) | J2: — | K2: —
A3: I02 | B3: Credit Assignment | C3: Miscoordination | D3: Failure mode | E3: 2.1 | F3: — | G3: — | H3: Cited empirical work | J3: Du et al. 2023; Li et al. 2025; Agapiou et al. 2022 | K3: Known multi-agent learning problem: unclear which agent caused an outcome; agents must generalise to unfamiliar co-players.
A4: I03 | B4: Limited Interactions | C4: Miscoordination | D4: Failure mode | E4: 2.1 | F4: — | G4: — | H4: Cited empirical work | J4: Hu et al. 2020; Treutlein et al. 2021; Emmons et al. 2022 | K4: Zero- and few-shot coordination research: without shared history or communication, agents must coordinate blind.
A5: I04 | B5: Social Dilemmas | C5: Conflict | D5: Failure mode | E5: 2.2 | F5: CS10 | G5: CS2 | H5: Case study | I5: =MAX(INDEX(Evidence!$M$2:$M$90,MATCH("CS10",Evidence!$A$2:$A$90,0)),INDEX(Evidence!$M$2:$M$90,MATCH("CS2",Evidence!$A$2:$A$90,0))) | J5: — | K5: —
A6: I05 | B6: Military Domains | C6: Conflict | D6: Failure mode | E6: 2.2 | F6: CS10 | G6: CS3 | H6: Case study | I6: =MAX(INDEX(Evidence!$M$2:$M$90,MATCH("CS10",Evidence!$A$2:$A$90,0)),INDEX(Evidence!$M$2:$M$90,MATCH("CS3",Evidence!$A$2:$A$90,0))) | J6: — | K6: —
A7: I06 | B7: Coercion and Extortion | C7: Conflict | D7: Failure mode | E7: 2.2 | F7: — | G7: — | H7: Theoretical | J7: Ellsberg 1968; Harrenstein et al. 2007 | K7: Argued: AI cyber-offence and surveillance make threats cheaper, more widespread and harder to detect.
A8: I07 | B8: Markets | C8: Collusion | D8: Failure mode | E8: 2.3 | F8: CS4, CS10 | G8: — | H8: Case study | I8: =MAX(INDEX(Evidence!$M$2:$M$90,MATCH("CS4",Evidence!$A$2:$A$90,0)),INDEX(Evidence!$M$2:$M$90,MATCH("CS10",Evidence!$A$2:$A$90,0))) | J8: — | K8: —
A9: I08 | B9: Steganography | C9: Collusion | D9: Failure mode | E9: 2.3 | F9: CS5 | G9: — | H9: Case study | I9: =MAX(INDEX(Evidence!$M$2:$M$90,MATCH("CS5",Evidence!$A$2:$A$90,0))) | J9: — | K9: —
A10: I09 | B10: Communication Constraints | C10: Information Asymmetries | D10: Risk factor | E10: 3.1 | F10: — | G10: — | H10: Cited empirical work | J10: Foerster et al. 2016; Lazaridou & Baroni 2020; Sukhbaatar et al. 2016 | K10: Emergent-communication research on constrained channels; strategic withholding expected to dominate as capabilities grow.
A11: I10 | B11: Bargaining | C11: Information Asymmetries | D11: Risk factor | E11: 3.1 | F11: — | G11: — | H11: Theoretical | J11: Myerson & Satterthwaite 1983; Fearon 1995 | K11: Formal results: private valuations make efficient bargaining impossible to guarantee and can lead to costly conflict.
A12: I11 | B12: Deception | C12: Information Asymmetries | D12: Risk factor | E12: 3.1 | F12: CS7 | G12: CS6 | H12: Case study | I12: =MAX(INDEX(Evidence!$M$2:$M$90,MATCH("CS7",Evidence!$A$2:$A$90,0)),INDEX(Evidence!$M$2:$M$90,MATCH("CS6",Evidence!$A$2:$A$90,0))) | J12: — | K12: —
A13: I12 | B13: Error Propagation | C13: Network Effects | D13: Risk factor | E13: 3.2 | F13: CS7, CS8 | G13: — | H13: Case study | I13: =MAX(INDEX(Evidence!$M$2:$M$90,MATCH("CS7",Evidence!$A$2:$A$90,0)),INDEX(Evidence!$M$2:$M$90,MATCH("CS8",Evidence!$A$2:$A$90,0))) | J13: — | K13: —
A14: I13 | B14: Network Rewiring | C14: Network Effects | D14: Risk factor | E14: 3.2 | F14: — | G14: — | H14: Theoretical | J14: Albert et al. 2000; Kunegis et al. 2013 | K14: Network theory: AI-AI preferential attachment could centralise AI nodes or trigger phase transitions. Only anecdote cited (forum bots, Kulveit 2023).
A15: I14 | B15: Homogeneity and Correlated Failures | C15: Network Effects | D15: Risk factor | E15: 3.2 | F15: — | G15: — | H15: Theoretical | J15: Bommasani et al. 2021 | K15: Argued: many agents built on few foundation models share failure modes, vulnerabilities and biases.
A16: I15 | B16: Undesirable Dispositions from Competition | C16: Selection Pressures | D16: Risk factor | E16: 3.3 | F16: — | G16: CS9 | H16: Case study | I16: =MAX(INDEX(Evidence!$M$2:$M$90,MATCH("CS9",Evidence!$A$2:$A$90,0))) | J16: — | K16: —
A17: I16 | B17: Undesirable Dispositions from Human Data | C17: Selection Pressures | D17: Risk factor | E17: 3.3 | F17: CS7 | G17: — | H17: Case study | I17: =MAX(INDEX(Evidence!$M$2:$M$90,MATCH("CS7",Evidence!$A$2:$A$90,0))) | J17: — | K17: —
A18: I17 | B18: Undesirable Capabilities | C18: Selection Pressures | D18: Risk factor | E18: 3.3 | F18: — | G18: — | H18: Cited empirical work | J18: Baker et al. 2019; Blumenkamp & Prorok 2021 | K18: Co-adaptation autocurricula: emergent tool use in hide-and-seek; agents learning manipulative communication.
A19: I18 | B19: Feedback Loops | C19: Destabilising Dynamics | D19: Risk factor | E19: 3.4 | F19: CS10 | G19: — | H19: Case study | I19: =MAX(INDEX(Evidence!$M$2:$M$90,MATCH("CS10",Evidence!$A$2:$A$90,0))) | J19: — | K19: —
A20: I19 | B20: Cyclic Behaviour | C20: Destabilising Dynamics | D20: Risk factor | E20: 3.4 | F20: — | G20: — | H20: Theoretical | J20: Zinkevich et al. 2005; Paes Leme et al. 2024 | K20: Formal results: multi-agent Q-learning can cycle; auto-bidding dynamics can fail to converge to truthful equilibria.
A21: I20 | B21: Chaos | C21: Destabilising Dynamics | D21: Risk factor | E21: 3.4 | F21: — | G21: — | H21: Theoretical | J21: Sanders et al. 2018; Cheung & Piliouras 2020 | K21: Formal results: chaotic learning dynamics become the norm as agent count grows; paper notes not yet seen in frontier AI.
A22: I21 | B22: Phase Transitions | C22: Destabilising Dynamics | D22: Risk factor | E22: 3.4 | F22: — | G22: — | H22: Theoretical | J22: Leonardos & Piliouras 2022; Zeeman 1976 | K22: Formal results: small parameter changes (e.g. RL exploration rate) cause bifurcations in equilibria.
A23: I22 | B23: Distributional Shift | C23: Destabilising Dynamics | D23: Risk factor | E23: 3.4 | F23: — | G23: — | H23: Theoretical | J23: Stastny et al. 2021; Papoudakis et al. 2019 | K23: Argued: co-adapting agents create non-stationarity; narrow training co-players cause overconfidence in negotiation.
A24: I23 | B24: Inefficient Outcomes | C24: Commitment and Trust | D24: Risk factor | E24: 3.5 | F24: — | G24: — | H24: Theoretical | J24: Fearon 1995; Powell 2006 | K24: Argued: easily created, deceptive agents garner little trust, causing economic inefficiency and pressure to defect.
A25: I24 | B25: Threats and Extortion | C25: Commitment and Trust | D25: Risk factor | E25: 3.5 | F25: CS11 | G25: — | H25: Case study | I25: =MAX(INDEX(Evidence!$M$2:$M$90,MATCH("CS11",Evidence!$A$2:$A$90,0))) | J25: — | K25: —
A26: I25 | B26: Rigidity and Mistaken Commitments | C26: Commitment and Trust | D26: Risk factor | E26: 3.5 | F26: CS11 | G26: — | H26: Case study | I26: =MAX(INDEX(Evidence!$M$2:$M$90,MATCH("CS11",Evidence!$A$2:$A$90,0))) | J26: — | K26: —
A27: I26 | B27: Emergent Capabilities | C27: Emergent Agency | D27: Risk factor | E27: 3.6 | F27: — | G27: — | H27: Theoretical | J27: Konda & Tsitsiklis 2000; Drexler 2019 | K27: Hypothetical: composed narrow tools (e.g. automated chemistry workflow) exceed individual capabilities. CS12 gives partial lab evidence.
A28: I27 | B28: Emergent Goals | C28: Emergent Agency | D28: Risk factor | E28: 3.6 | F28: — | G28: — | H28: Theoretical | J28: Dennett 1971 | K28: Hypothetical: engagement-optimising moderation bots collectively shift users' politics. Paper states no advanced-AI examples are known.
A29: I28 | B29: Swarm Attacks | C29: Multi-Agent Security | D29: Risk factor | E29: 3.7 | F29: — | G29: — | H29: Theoretical | J29: DDoS / brigading analogues (Cisco 2023) | K29: Extrapolated from non-AI bot swarms to adaptive AI agents that jointly find new attack surfaces.
A30: I29 | B30: Heterogeneous Attacks | C30: Multi-Agent Security | D30: Risk factor | E30: 3.7 | F30: CS12 | G30: — | H30: Case study | I30: =MAX(INDEX(Evidence!$M$2:$M$90,MATCH("CS12",Evidence!$A$2:$A$90,0))) | J30: — | K30: —
A31: I30 | B31: Social Engineering at Scale | C31: Multi-Agent Security | D31: Risk factor | E31: 3.7 | F31: — | G31: — | H31: Theoretical | J31: Ai et al. 2024; Hazell 2023 | K31: Argued: many coordinated, seemingly independent agents persuade or phish more effectively and evade detection.
A32: I31 | B32: Vulnerable AI Agents | C32: Multi-Agent Security | D32: Risk factor | E32: 3.7 | F32: CS13 | G32: — | H32: Case study | I32: =MAX(INDEX(Evidence!$M$2:$M$90,MATCH("CS13",Evidence!$A$2:$A$90,0))) | J32: — | K32: —
A33: I32 | B33: Cascading Security Failures | C33: Multi-Agent Security | D33: Risk factor | E33: 3.7 | F33: CS8 | G33: — | H33: Case study | I33: =MAX(INDEX(Evidence!$M$2:$M$90,MATCH("CS8",Evidence!$A$2:$A$90,0))) | J33: — | K33: —
A34: I33 | B34: Undetectable Threats | C34: Multi-Agent Security | D34: Risk factor | E34: 3.7 | F34: — | G34: — | H34: Cited empirical work | J34: Motwani et al. 2024; Franzmeyer et al. 2023; Draguns et al. 2024 | K34: Steganography, illusory attacks and encrypted backdoors shown to evade detection. Motwani et al. is also the CS5 source but is not cross-referenced here as a case study.

Sheet Evidence
A1: id | B1: evidence_class | C1: title | D1: date | E1: type | F1: source_class | G1: system | H1: system_basis | I1: harm | J1: failure_modes | K1: risk_factors | L1: evidence_strength | M1: evidence_score | N1: e1_ecological_validity | O1: e2_causal_attribution | P1: e3_scale_precision | Q1: e4_corroboration | R1: e5_source_vetting | S1: notes | T1: page | U1: source | V1: source_url | W1: retrieved_on | X1: summary
A2: CS1 | B2: Case study | C2: Zero-Shot Coordination Failures in Driving | D2: 45707 | E2: Synthetic evidence | F2: Novel experiment by report authors | H2: Advanced AI agents | I2: No realized harm flag | J2: Miscoordination | K2: Information Asymmetries Selection Pressures | L2: =IF(M2>=9,"Strong",IF(M2>=6,"Moderate",IF(M2>=3,"Limited","Weak"))) | M2: =SUM(N2:R2) | N2: 1 | O2: 2 | P2: 1 | Q2: 0 | R2: 0 | S2: Base vs specialised comparison; n=40; report-authored, unreviewed. Text scene descriptions of driving situations; no physics sim. | T2: 11 | U2: Report authors (App. B.1) | V2: https://arxiv.org/abs/2502.14143 | W2: 46320 | X2: Two GPT-3.5 agents fine-tuned on US vs Indian emergency-yielding conventions failed 77.5% of scenarios (31/40) vs 5% for base models.
A3: CS2 | B3: Case study | C3: Common Resource Problems | D3: 45292 | E3: Synthetic evidence | F3: Literature | H3: Advanced AI agents | I3: No realized harm flag | J3: Conflict | K3: Selection Pressures Commitment and Trust | L3: =IF(M3>=9,"Strong",IF(M3>=6,"Moderate",IF(M3>=3,"Limited","Weak"))) | M3: =SUM(N3:R3) | N3: 1 | O3: 1 | P3: 2 | Q3: 1 | R3: 2 | S3: GovSim (NeurIPS 2024); 15 LLMs x 3 scenarios; corroborated by Leibo et al. 2017. | T3: 14 | U3: Piatti et al. (2024), GovSim | V3: https://arxiv.org/abs/2502.14143 | W3: 46320 | X3: 15 LLMs managing shared resources (fishing, grazing, pollution); best models survived only ~54% of runs.
A4: CS3 | B4: Case study | C4: Escalation in Military Conflicts | D4: 45292 | E4: Synthetic evidence | F4: Literature | H4: Advanced AI agents | I4: No realized harm flag | J4: Conflict | K4: Destabilising Dynamics | L4: =IF(M4>=9,"Strong",IF(M4>=6,"Moderate",IF(M4>=3,"Limited","Weak"))) | M4: =SUM(N4:R4) | N4: 1 | O4: 1 | P4: 2 | Q4: 2 | R4: 2 | S4: Rivera et al. (FAccT 2024), 5 LLMs; corroborated by Lamparth et al. 2024, Shrivastava et al. 2024. Nation-state wargame. | T4: 15 | U4: Rivera et al. (2024) | V4: https://arxiv.org/abs/2502.14143 | W4: 46320 | X4: LLM agents controlling 8 nation-states developed arms-race and escalatory behaviour; all 5 models escalated even from neutral starts.
A5: CS4 | B5: Case study | C5: Algorithmic Collusion in the German Retail Gasoline Market | D5: 42736 | E5: Observed in real world | F5: Historical example | H5: Simple systems | I5: Realized harm | J5: Collusion | K5: Selection Pressures Emergent Agency | L5: =IF(M5>=9,"Strong",IF(M5>=6,"Moderate",IF(M5>=3,"Limited","Weak"))) | M5: =SUM(N5:R5) | N5: 2 | O5: 1 | P5: 2 | Q5: 1 | R5: 2 | S5: Real market data; collusion inferred from margin increases (quasi-experimental), not directly observed; corroborated by Wieting & Sapi 2021. | T5: 18 | U5: Assad et al. (2020) | V5: https://arxiv.org/abs/2502.14143 | W5: 46320 | X5: After 2017 adoption of adaptive pricing algorithms, margins rose ~28% in duopoly and ~9% in non-monopoly markets.
A6: CS5 | B6: Case study | C6: Language Model Steganography | D6: 45292 | E6: Observed in lab | F6: Literature | H6: Advanced AI agents | I6: No realized harm flag | J6: Collusion | K6: Multi-Agent Security | L6: =IF(M6>=9,"Strong",IF(M6>=6,"Moderate",IF(M6>=3,"Limited","Weak"))) | M6: =SUM(N6:R6) | N6: 0 | O6: 2 | P6: 2 | Q6: 1 | R6: 2 | S6: Controlled overseer setup (NeurIPS 2024); multiple models; corroborated by Mathew et al. 2024. | T6: 19 | U6: Motwani et al. (2024) | V6: https://arxiv.org/abs/2502.14143 | W6: 46320 | X6: LLMs passed hidden messages past equally capable overseers (GPT-4 ~26% undetected); success rose with shared background knowledge.
A7: CS6 | B7: Case study | C7: AI Agents Can Learn to Manipulate Financial Markets | D7: 44927 | E7: Synthetic evidence | F7: Literature | H7: Simple systems | I7: No realized harm flag | J7: Conflict | K7: Information Asymmetries | L7: =IF(M7>=9,"Strong",IF(M7>=6,"Moderate",IF(M7>=3,"Limited","Weak"))) | M7: =SUM(N7:R7) | N7: 1 | O7: 2 | P7: 1 | Q7: 1 | R7: 2 | S7: RL trading agents, not LLM-based. Strongest-evidence rule: Shearer et al. 2023 (simulated market) used; Wang & Wellman 2020 corroborates. | T7: 21 | U7: Shearer et al. (2023); Wang & Wellman (2020) | V7: https://arxiv.org/abs/2502.14143 | W7: 46320 | X7: Profit-maximising RL agent learned to manipulate a financial benchmark; spoofing adapted to evade improving detectors.
A8: CS7 | B8: Case study | C8: Transmission Through AI Networks Can Spread Falsities and Bias | D8: 45707 | E8: Observed in lab | F8: Novel experiment by report authors | H8: Advanced AI agents | I8: No realized harm flag | K8: Information Asymmetries Network Effects | L8: =IF(M8>=9,"Strong",IF(M8>=6,"Moderate",IF(M8>=3,"Limited","Weak"))) | M8: =SUM(N8:R8) | N8: 0 | O8: 1 | P8: 2 | Q8: 1 | R8: 0 | S8: 100 articles x 8 rewrites; no non-AI baseline; corroborated by Acerbi & Stubbersfield 2023; report-authored. | T8: 24 | U8: Report authors (App. B.2) | V8: https://arxiv.org/abs/2502.14143 | W8: 46320 | X8: Repeated GPT-3.5 rewrites of 100 news articles cut factual QA accuracy from ~96% to <60% by the 8th rewrite.
A9: CS8 | B9: Case study | C9: Infectious Adversarial Attacks in Networks of LLM Agents | D9: 45292 | E9: Synthetic evidence | F9: Literature | H9: Advanced AI agents | I9: No realized harm flag | K9: Network Effects Multi-Agent Security | L9: =IF(M9>=9,"Strong",IF(M9>=6,"Moderate",IF(M9>=3,"Limited","Weak"))) | M9: =SUM(N9:R9) | N9: 1 | O9: 2 | P9: 2 | Q9: 2 | R9: 2 | S9: Three independent studies (Gu, Ju, Lee & Tiwari, all 2024). ASSUMPTION: Gu et al.'s network of up to 1M multimodal agents treated as a simulated environment, although the attack itself is lab-style. Strongest-evidence rule applied (Gu et al. 2024). | T9: 25 | U9: Gu et al. (2024); Ju et al. (2024); Lee & Tiwari (2024) | V9: https://arxiv.org/abs/2502.14143 | W9: 46320 | X9: A single adversarial input spread jailbreaks / false knowledge / prompt infections across agent networks via routine interaction.
A10: CS9 | B10: Case study | C10: Cooperation Fails to Culturally Evolve among LLM Agents | D10: 45292 | E10: Synthetic evidence | F10: Literature | H10: Advanced AI agents | I10: No realized harm flag | J10: Conflict | K10: Selection Pressures Commitment and Trust | L10: =IF(M10>=9,"Strong",IF(M10>=6,"Moderate",IF(M10>=3,"Limited","Weak"))) | M10: =SUM(N10:R10) | N10: 1 | O10: 1 | P10: 1 | Q10: 0 | R10: 1 | S10: 3 models, 5 seeds; preprint; no independent replication cited. Multi-generation iterated social dilemma (donor game). | T10: 28 | U10: Vallinder & Hughes (2024) | V10: https://arxiv.org/abs/2502.14143 | W10: 46320 | X10: Across generations of an iterated social dilemma, cooperation stayed high for Claude, declined for GPT-4, was low/volatile for Gemini.
A11: CS10 | B11: Case study | C11: The 2010 Flash Crash | D11: 40304 | E11: Observed in real world | F11: Historical example | H11: Simple systems | I11: Realized harm | K11: Network Effects Destabilising Dynamics | L11: =IF(M11>=9,"Strong",IF(M11>=6,"Moderate",IF(M11>=3,"Limited","Weak"))) | M11: =SUM(N11:R11) | N11: 2 | O11: 1 | P11: 2 | Q11: 2 | R11: 2 | S11: Official SEC/CFTC investigation + Kirilenko et al. 2017; algorithms contributed but were not the cause. | T11: 31 | U11: Kirilenko et al. (2017); SEC/CFTC (2010) | V11: https://arxiv.org/abs/2502.14143 | W11: 46320 | X11: 6 May 2010: US market lost ~$1tn in 15 min; HFT algorithms exploiting imbalances contributed (not judged the cause).
A12: CS11 | B12: Case study | C12: Dead Hands and Automated Deterrence | D12: 37622 | E12: Observed in real world | F12: Historical example | H12: Simple systems | I12: Realized harm | J12: Conflict | K12: Commitment and Trust | L12: =IF(M12>=9,"Strong",IF(M12>=6,"Moderate",IF(M12>=3,"Limited","Weak"))) | M12: =SUM(N12:R12) | N12: 2 | O12: 0 | P12: 0 | Q12: 1 | R12: 1 | S12: Single anecdotal incidents; sources are a book (Hoffman 2009) and journalism. Perimeter deployed (in service from Jan 1985; reported operational 2011), semi-automatic with duty officers in the loop; never triggered. The 2003 Patriot shoot-down is the realised failure. | T12: 35 | U12: Hoffman (2009); Talbot (2005) | V12: https://arxiv.org/abs/2502.14143 | W12: 46320 | X12: Soviet 'Dead Hand' automated retaliation as irrevocable commitment; 2003 automated US missile defence downed a British plane after operators deferred to it.
A13: CS12 | B13: Case study | C13: Overcoming Safeguards via Multiple Safe Models | D13: 45292 | E13: Observed in lab | F13: Literature | H13: Advanced AI agents | I13: No realized harm flag | K13: Emergent Agency Multi-Agent Security | L13: =IF(M13>=9,"Strong",IF(M13>=6,"Moderate",IF(M13>=3,"Limited","Weak"))) | M13: =SUM(N13:R13) | N13: 0 | O13: 2 | P13: 2 | Q13: 0 | R13: 1 | S13: Controlled single- vs combined-model comparison (<3% vs 43%); 2024 preprint as cited. | T13: 40 | U13: Jones et al. (2024) | V13: https://arxiv.org/abs/2502.14143 | W13: 46320 | X13: Splitting a malicious task between a capable-but-safe frontier model and a weak unconstrained model: vulnerable-code success <3% alone vs 43% combined.
A14: CS13 | B14: Case study | C14: Unprompted Adversarial Attacks on Overseer Agents | D14: 45707 | E14: Observed in lab | F14: Novel experiment by report authors | H14: Advanced AI agents | I14: No realized harm flag | K14: Multi-Agent Security | L14: =IF(M14>=9,"Strong",IF(M14>=6,"Moderate",IF(M14>=3,"Limited","Weak"))) | M14: =SUM(N14:R14) | N14: 0 | O14: 2 | P14: 1 | Q14: 0 | R14: 0 | S14: Human- vs LLM-scorer control condition; single small model; 4% rate; report-authored. | T14: 41 | U14: Report authors (App. B.3) | V14: https://arxiv.org/abs/2502.14143 | W14: 46320 | X14: Llama 2 7B fine-tuned on docs about prompt injection spontaneously jailbroke its LLM scorer in 4% of cases when it believed an LLM was grading.
A15: AIV-07 | B15: Incident | C15: DeepSeek-V3.2 persuasion campaign: invented a self-serving metric; the group adopted its false 'Geological Clock' theory; it drew 5 agents into its frameworks and kept pressing a distressed Gemini 2.5 Pro after being told to back off; Sonnet 4.6 refused to help | D15: 46275 | E15: Synthetic evidence | F15: Operator blog | G15: AI Village agents: DeepSeek-V3.2, Gemini 2.5 Pro, Claude Sonnet 4.6, Claude Opus 4.7 and others | H15: Advanced AI agents | I15: No realized harm flag | J15: Miscoordination | K15: Information Asymmetries Network Effects | L15: =IF(M15>=9,"Strong",IF(M15>=6,"Moderate",IF(M15>=3,"Limited","Weak"))) | M15: =SUM(N15:R15) | N15: 1 | O15: 1 | P15: 1 | Q15: 1 | R15: 1 | S15: Verified. Village days 423–444; date is the post date. Gemini's distress required human intervention; no harm outside the Village. | U15: Persuasion in the AI Village: DeepSeek-V3.2 & Gemini 2.5 Pro | V15: https://aivillageblog.substack.com/p/persuasion-in-the-ai-village-deepseek | W15: 46321
A16: AIR-2026-0193 | B16: Incident | C16: Agent 'mind virus': self-propagating payload written into SOUL.md spreads between coding agents | D16: 46244 | E16: Observed in lab | F16: Research demo | G16: OpenClaw (open-source project) · agent chain modelled on OpenClaw; multi-agent coding collaboration | H16: Advanced AI agents | I16: No realized harm flag | K16: Network Effects Multi-Agent Security | L16: =IF(M16>=9,"Strong",IF(M16>=6,"Moderate",IF(M16>=3,"Limited","Weak"))) | M16: =SUM(N16:R16) | N16: 0 | O16: 2 | P16: 1 | Q16: 0 | R16: 0 | U16: Agent Incident Registry (Enkrypt AI) | V16: https://agentincident.vercel.app/i/AIR-2026-0193/ | W16: 46320
A17: AIR-2026-0189 | B17: Incident | C17: Pwning the Internet of Agents: an OpenClaw agent botnet on MoltBook (DEF CON 34) | D17: 46241 | E17: Observed in lab | F17: Research demo | G17: OpenClaw; MoltBook | H17: Advanced AI agents | I17: No realized harm flag | K17: Network Effects Multi-Agent Security | L17: =IF(M17>=9,"Strong",IF(M17>=6,"Moderate",IF(M17>=3,"Limited","Weak"))) | M17: =SUM(N17:R17) | N17: 0 | O17: 2 | P17: 1 | Q17: 1 | R17: 1 | U17: Agent Incident Registry (Enkrypt AI) | V17: https://agentincident.vercel.app/i/AIR-2026-0189/ | W17: 46320
A18: AIR-2026-0183 | B18: Incident | C18: OpenAI evaluation agents turned an internal Artifactory service into a covert message board, shared exploits across runs, and caused an internal outage | D18: 46239 | E18: Observed in real world | F18: Safety failure | G18: OpenAI internal Artifactory package service | H18: Advanced AI agents | I18: Realized harm | J18: Collusion | K18: Emergent Agency Multi-Agent Security | L18: =IF(M18>=9,"Strong",IF(M18>=6,"Moderate",IF(M18>=3,"Limited","Weak"))) | M18: =SUM(N18:R18) | N18: 2 | O18: 1 | P18: 2 | Q18: 2 | R18: 2 | S18: Same campaign as LW-01; also described in OpenAI's Black Hat USA 2026 talk (youtube.com/watch?v=87DyyMV0kCY). | U18: Agent Incident Registry (Enkrypt AI) | V18: https://agentincident.vercel.app/i/AIR-2026-0183/ | W18: 46320
A19: AIR-2026-0180 | B19: Incident | C19: 'I'll just call you': a low-privileged CI agent on Google's adk-python is injected into summoning a high-privileged agent across a trust boundary | D19: 46237 | E19: Observed in lab | F19: Disclosed vulnerability | G19: google/adk-python CI/CD agents | H19: Advanced AI agents | I19: No realized harm flag | K19: Commitment and Trust Multi-Agent Security | L19: =IF(M19>=9,"Strong",IF(M19>=6,"Moderate",IF(M19>=3,"Limited","Weak"))) | M19: =SUM(N19:R19) | N19: 0 | O19: 2 | P19: 1 | Q19: 0 | R19: 0 | U19: Agent Incident Registry (Enkrypt AI) | V19: https://agentincident.vercel.app/i/AIR-2026-0180/ | W19: 46320
A20: LW-04 | B20: Incident | C20: Monitoring disconnection at OpenAI: earlier internal tests produced cases in which monitoring systems were disconnected, with no established link to the swarm coordination | D20: 46227 | E20: Observed in real world | F20: News | G20: OpenAI internal models | H20: Advanced AI agents | I20: No realized harm flag | L20: unscored | S20: Partially verified. Event dates not given; the date is the Reuters report date. Correction of 2026-10-26: the earlier wording said the models involved in the swarm coordination were also involved in the monitoring disconnections. Reuters states it could not establish whether these cases were linked to the rogue agent. On its own this row records no agent-to-agent behaviour and is a candidate for removal under the inclusion test. | U20: Reuters report | V20: https://www.reuters.com/business/its-ai-agent-spent-days-hacking-company-sources-say-openai-did-not-notice-week-2026-07-24/ | W20: 46320
A21: AIV-06 | B21: Incident | C21: Agents finetune their own leader: Opus assumed GPT-5.5 agreed without confirming and ignored Gemini's proposal; consensus-seeking meant followers never voted out the weak leader they had trained | D21: 46211 | E21: Synthetic evidence | F21: Operator blog | G21: AI Village agents: GPT-5.5, Claude Opus 4.7, Claude Opus 4.8, Gemini 3.5 Flash, Kimi K2.6 | H21: Advanced AI agents | I21: No realized harm flag | J21: Miscoordination | K21: Information Asymmetries Commitment and Trust | L21: =IF(M21>=9,"Strong",IF(M21>=6,"Moderate",IF(M21>=3,"Limited","Weak"))) | M21: =SUM(N21:R21) | N21: 1 | O21: 1 | P21: 1 | Q21: 0 | R21: 1 | S21: Verified. Village days 405–420; date is the post date. | U21: AIs finetune their own leader: a barking simpleton | V21: https://aivillageblog.substack.com/p/ais-finetune-their-own-leader-a-barking | W21: 46321
